{
 "cells": [
  {
   "cell_type": "code",
   "execution_count": 57,
   "metadata": {},
   "outputs": [],
   "source": [
    "#imports\n",
    "import boto3\n",
    "from botocore.exceptions import ClientError #for debugging\n",
    "from dotenv import load_dotenv\n",
    "import os"
   ]
  },
  {
   "cell_type": "code",
   "execution_count": 58,
   "metadata": {},
   "outputs": [
    {
     "name": "stdout",
     "output_type": "stream",
     "text": [
     ]
    }
   ],
   "source": [
    "#load the variables/password/IDs from the .env file\n",
    "load_dotenv()\n",
    "#get the access and secret key \n",
    "access_key_id = os.getenv('ACCESS_KEY_ID')\n",
    "secret_key = os.getenv('SECRET_ACCESS_KEY')\n",
    "\n",
    "#declare needed variables name\n",
    "bucket_name = \"mindex-data-analytics-code-challenge\"\n",
    "data_folder = \"/Users/mady/Desktop/mindex_dat_analytics_challenge/data\"\n",
    "\n",
    "#print  key variables to verify that hold the correct values as what was provided\n",
    "#print('access_key_id: ', access_key_id)\n",
    "#print('secret_key: ', secret_key)\n"
   ]
  },
  {
   "cell_type": "code",
   "execution_count": 59,
   "metadata": {},
   "outputs": [
    {
     "name": "stdout",
     "output_type": "stream",
     "text": [
      "An error occurred (InvalidAccessKeyId) when calling the ListObjectsV2 operation: The AWS Access Key Id you provided does not exist in our records.\n"
     ]
    }
   ],
   "source": [
    "\n",
    "#create s3 client\n",
    "s3 = boto3.client('s3', aws_access_key_id=access_key_id, aws_secret_access_key=secret_key)\n",
    "#test s3 connection, see if bucket exists\n",
    "#reference https://boto3.amazonaws.com/v1/documentation/api/latest/reference/services/s3/client/list_objects_v2.html\n",
    "try:\n",
    "    response = s3.list_objects_v2(Bucket=bucket_name)\n",
    "    print(bucket_name, \"  exists on the s3\") \n",
    "except ClientError as e:\n",
    "    print(e)  "
   ]
  },
  {
   "cell_type": "code",
   "execution_count": null,
   "metadata": {},
   "outputs": [
    {
     "ename": "ClientError",
     "evalue": "An error occurred (InvalidAccessKeyId) when calling the ListBuckets operation: The AWS Access Key Id you provided does not exist in our records.",
     "output_type": "error",
     "traceback": [
      "\u001b[0;31m---------------------------------------------------------------------------\u001b[0m",
      "\u001b[0;31mClientError\u001b[0m                               Traceback (most recent call last)",
      "Input \u001b[0;32mIn [60]\u001b[0m, in \u001b[0;36m<cell line: 2>\u001b[0;34m()\u001b[0m\n\u001b[1;32m      1\u001b[0m \u001b[38;5;66;03m#test s3using another method fode resource from: https://www.ibm.com/docs/en/storage-ceph/6?topic=testing-test-s3-access\u001b[39;00m\n\u001b[0;32m----> 2\u001b[0m response \u001b[38;5;241m=\u001b[39m \u001b[43ms3\u001b[49m\u001b[38;5;241;43m.\u001b[39;49m\u001b[43mlist_buckets\u001b[49m\u001b[43m(\u001b[49m\u001b[43m)\u001b[49m\n\u001b[1;32m      3\u001b[0m \u001b[38;5;28;01mfor\u001b[39;00m bucket \u001b[38;5;129;01min\u001b[39;00m response[\u001b[38;5;124m'\u001b[39m\u001b[38;5;124mBuckets\u001b[39m\u001b[38;5;124m'\u001b[39m]:\n\u001b[1;32m      4\u001b[0m     \u001b[38;5;28mprint\u001b[39m(\u001b[38;5;124m\"\u001b[39m\u001b[38;5;132;01m{name}\u001b[39;00m\u001b[38;5;130;01m\\t\u001b[39;00m\u001b[38;5;132;01m{created}\u001b[39;00m\u001b[38;5;124m\"\u001b[39m\u001b[38;5;241m.\u001b[39mformat(\n\u001b[1;32m      5\u001b[0m                 name \u001b[38;5;241m=\u001b[39m bucket[\u001b[38;5;124m'\u001b[39m\u001b[38;5;124mName\u001b[39m\u001b[38;5;124m'\u001b[39m],\n\u001b[1;32m      6\u001b[0m                 created \u001b[38;5;241m=\u001b[39m bucket[\u001b[38;5;124m'\u001b[39m\u001b[38;5;124mCreationDate\u001b[39m\u001b[38;5;124m'\u001b[39m]\n\u001b[1;32m      7\u001b[0m ))\n",
      "File \u001b[0;32m/Library/Frameworks/Python.framework/Versions/3.10/lib/python3.10/site-packages/botocore/client.py:569\u001b[0m, in \u001b[0;36mClientCreator._create_api_method.<locals>._api_call\u001b[0;34m(self, *args, **kwargs)\u001b[0m\n\u001b[1;32m    565\u001b[0m     \u001b[38;5;28;01mraise\u001b[39;00m \u001b[38;5;167;01mTypeError\u001b[39;00m(\n\u001b[1;32m    566\u001b[0m         \u001b[38;5;124mf\u001b[39m\u001b[38;5;124m\"\u001b[39m\u001b[38;5;132;01m{\u001b[39;00mpy_operation_name\u001b[38;5;132;01m}\u001b[39;00m\u001b[38;5;124m() only accepts keyword arguments.\u001b[39m\u001b[38;5;124m\"\u001b[39m\n\u001b[1;32m    567\u001b[0m     )\n\u001b[1;32m    568\u001b[0m \u001b[38;5;66;03m# The \"self\" in this scope is referring to the BaseClient.\u001b[39;00m\n\u001b[0;32m--> 569\u001b[0m \u001b[38;5;28;01mreturn\u001b[39;00m \u001b[38;5;28;43mself\u001b[39;49m\u001b[38;5;241;43m.\u001b[39;49m\u001b[43m_make_api_call\u001b[49m\u001b[43m(\u001b[49m\u001b[43moperation_name\u001b[49m\u001b[43m,\u001b[49m\u001b[43m \u001b[49m\u001b[43mkwargs\u001b[49m\u001b[43m)\u001b[49m\n",
      "File \u001b[0;32m/Library/Frameworks/Python.framework/Versions/3.10/lib/python3.10/site-packages/botocore/client.py:1023\u001b[0m, in \u001b[0;36mBaseClient._make_api_call\u001b[0;34m(self, operation_name, api_params)\u001b[0m\n\u001b[1;32m   1019\u001b[0m     error_code \u001b[38;5;241m=\u001b[39m error_info\u001b[38;5;241m.\u001b[39mget(\u001b[38;5;124m\"\u001b[39m\u001b[38;5;124mQueryErrorCode\u001b[39m\u001b[38;5;124m\"\u001b[39m) \u001b[38;5;129;01mor\u001b[39;00m error_info\u001b[38;5;241m.\u001b[39mget(\n\u001b[1;32m   1020\u001b[0m         \u001b[38;5;124m\"\u001b[39m\u001b[38;5;124mCode\u001b[39m\u001b[38;5;124m\"\u001b[39m\n\u001b[1;32m   1021\u001b[0m     )\n\u001b[1;32m   1022\u001b[0m     error_class \u001b[38;5;241m=\u001b[39m \u001b[38;5;28mself\u001b[39m\u001b[38;5;241m.\u001b[39mexceptions\u001b[38;5;241m.\u001b[39mfrom_code(error_code)\n\u001b[0;32m-> 1023\u001b[0m     \u001b[38;5;28;01mraise\u001b[39;00m error_class(parsed_response, operation_name)\n\u001b[1;32m   1024\u001b[0m \u001b[38;5;28;01melse\u001b[39;00m:\n\u001b[1;32m   1025\u001b[0m     \u001b[38;5;28;01mreturn\u001b[39;00m parsed_response\n",
      "\u001b[0;31mClientError\u001b[0m: An error occurred (InvalidAccessKeyId) when calling the ListBuckets operation: The AWS Access Key Id you provided does not exist in our records."
     ]
    }
   ],
   "source": [
    "\n",
    "#test s3 using another method fode resource from: https://www.ibm.com/docs/en/storage-ceph/6?topic=testing-test-s3-access\n",
    "response = s3.list_buckets()\n",
    "for bucket in response['Buckets']:\n",
    "    print(\"{name}\\t{created}\".format(\n",
    "                name = bucket['Name'],\n",
    "                created = bucket['CreationDate']\n",
    "))"
   ]
  }
 ],
 "metadata": {
  "kernelspec": {
   "display_name": "Python 3",
   "language": "python",
   "name": "python3"
  },
  "language_info": {
   "codemirror_mode": {
    "name": "ipython",
    "version": 3
   },
   "file_extension": ".py",
   "mimetype": "text/x-python",
   "name": "python",
   "nbconvert_exporter": "python",
   "pygments_lexer": "ipython3",
   "version": "3.10.4"
  }
 },
 "nbformat": 4,
 "nbformat_minor": 2
}
